Bottle v0.12.13 server starting up (using AutoServer())...
Listening on http://0.0.0.0:80/
Hit Ctrl-C to quit.

182.254.86.149 - - [30/Apr/2018 19:19:30] "POST /?signature=ad668ae15c99345a603d1917cfda3d356d322511&timestamp=1525087170&nonce=249594429&openid=o2NddxHhZloQV55azmx8zVXv9mAQ HTTP/1.1" 200 467
182.254.86.144 - - [30/Apr/2018 19:19:31] "POST /?signature=7303d8b67385f68865345c7f32ebbc8fe4d90796&timestamp=1525087171&nonce=674321847&openid=o2NddxHhZloQV55azmx8zVXv9mAQ HTTP/1.1" 200 326
[E 180430 19:19:32 robot:405] Catch an exception
    Traceback (most recent call last):
      File "/usr/local/lib/python3.4/dist-packages/werobot/robot.py", line 399, in get_reply
        reply = handler(*args)
      File "reply_from_pymysql.py", line 117, in hello
        print('\u300a%s\u300b'%message.content)
    UnicodeEncodeError: 'ascii' codec can't encode characters in position 0-4: ordinal not in range(128)
[W 180430 19:19:33 robot:419] No handler responded message <werobot.messages.messages.TextMessage object at 0xb69dc38c>
182.254.86.149 - - [30/Apr/2018 19:19:33] "POST /?signature=3af269a30798c2e20d1ccac3b7f6c95ad9723b31&timestamp=1525087172&nonce=694414910&openid=o2NddxHhZloQV55azmx8zVXv9mAQ HTTP/1.1" 200 0
[E 180430 19:19:35 robot:405] Catch an exception
    Traceback (most recent call last):
      File "/usr/local/lib/python3.4/dist-packages/werobot/robot.py", line 399, in get_reply
        reply = handler(*args)
      File "reply_from_pymysql.py", line 117, in hello
        print('\u300a%s\u300b'%message.content)
    UnicodeEncodeError: 'ascii' codec can't encode characters in position 0-3: ordinal not in range(128)
[W 180430 19:19:35 robot:419] No handler responded message <werobot.messages.messages.TextMessage object at 0xb69dcb0c>
182.254.86.145 - - [30/Apr/2018 19:19:35] "POST /?signature=969da126b4dffdaf0f2ee85c06507a3a4984b712&timestamp=1525087175&nonce=685644684&openid=o2NddxJUox5Wz_SfVHH699WBZRcg HTTP/1.1" 200 0
[E 180430 19:19:37 robot:405] Catch an exception
    Traceback (most recent call last):
      File "/usr/local/lib/python3.4/dist-packages/werobot/robot.py", line 399, in get_reply
        reply = handler(*args)
      File "reply_from_pymysql.py", line 117, in hello
        print('\u300a%s\u300b'%message.content)
    UnicodeEncodeError: 'ascii' codec can't encode characters in position 0-4: ordinal not in range(128)
[W 180430 19:19:37 robot:419] No handler responded message <werobot.messages.messages.TextMessage object at 0xb69dcd6c>
182.254.86.154 - - [30/Apr/2018 19:19:37] "POST /?signature=912c9a16ad66ca087831d929d2c2b51f776dbbb6&timestamp=1525087177&nonce=328587886&openid=o2NddxHhZloQV55azmx8zVXv9mAQ HTTP/1.1" 200 0
[E 180430 19:19:40 robot:405] Catch an exception
    Traceback (most recent call last):
      File "/usr/local/lib/python3.4/dist-packages/werobot/robot.py", line 399, in get_reply
        reply = handler(*args)
      File "reply_from_pymysql.py", line 117, in hello
        print('\u300a%s\u300b'%message.content)
    UnicodeEncodeError: 'ascii' codec can't encode characters in position 0-4: ordinal not in range(128)
[W 180430 19:19:40 robot:419] No handler responded message <werobot.messages.messages.TextMessage object at 0xb69dcfec>
182.254.86.154 - - [30/Apr/2018 19:19:40] "POST /?signature=dae0aacbb926223eb114890cfb5b486a27a536c9&timestamp=1525087180&nonce=1917330653&openid=o2NddxHhZloQV55azmx8zVXv9mAQ HTTP/1.1" 200 0
[E 180430 19:19:43 robot:405] Catch an exception
    Traceback (most recent call last):
      File "/usr/local/lib/python3.4/dist-packages/werobot/robot.py", line 399, in get_reply
        reply = handler(*args)
      File "reply_from_pymysql.py", line 117, in hello
        print('\u300a%s\u300b'%message.content)
    UnicodeEncodeError: 'ascii' codec can't encode characters in position 0-7: ordinal not in range(128)
[W 180430 19:19:43 robot:419] No handler responded message <werobot.messages.messages.TextMessage object at 0xb6a0332c>
182.254.86.149 - - [30/Apr/2018 19:19:43] "POST /?signature=b4248f4a6b2296f6aa0e8328541f4651cd4dcdf7&timestamp=1525087183&nonce=858418666&openid=o2NddxLChTFP9QLsPBRKBmrHNS6Y HTTP/1.1" 200 0
[E 180430 19:19:45 robot:405] Catch an exception
    Traceback (most recent call last):
      File "/usr/local/lib/python3.4/dist-packages/werobot/robot.py", line 399, in get_reply
        reply = handler(*args)
      File "reply_from_pymysql.py", line 117, in hello
        print('\u300a%s\u300b'%message.content)
    UnicodeEncodeError: 'ascii' codec can't encode characters in position 0-4: ordinal not in range(128)
[W 180430 19:19:45 robot:419] No handler responded message <werobot.messages.messages.TextMessage object at 0xb6a0364c>
182.254.86.144 - - [30/Apr/2018 19:19:45] "POST /?signature=cc4f66d0cd3c7a05ea8183643252e17f2ec000d6&timestamp=1525087184&nonce=337563466&openid=o2NddxN-gkWQlMRr1wwRTDaqNF3I HTTP/1.1" 200 0
[W 180430 19:19:45 robot:419] No handler responded message <werobot.messages.events.ViewEvent object at 0xb6a038cc>
182.254.86.155 - - [30/Apr/2018 19:19:45] "POST /?signature=a578151eb46571bd90faa0ebe78ba94810b7d689&timestamp=1525087185&nonce=31109437&openid=o2NddxJUox5Wz_SfVHH699WBZRcg HTTP/1.1" 200 0
[E 180430 19:19:46 robot:405] Catch an exception
    Traceback (most recent call last):
      File "/usr/local/lib/python3.4/dist-packages/werobot/robot.py", line 399, in get_reply
        reply = handler(*args)
      File "reply_from_pymysql.py", line 117, in hello
        print('\u300a%s\u300b'%message.content)
    UnicodeEncodeError: 'ascii' codec can't encode characters in position 0-4: ordinal not in range(128)
[W 180430 19:19:46 robot:419] No handler responded message <werobot.messages.messages.TextMessage object at 0xb6a03c8c>
182.254.86.144 - - [30/Apr/2018 19:19:46] "POST /?signature=6016847ee8d63d2cc1d012c80acaf5d96f24f785&timestamp=1525087186&nonce=1685023927&openid=o2NddxHhZloQV55azmx8zVXv9mAQ HTTP/1.1" 200 0
