Bottle v0.12.13 server starting up (using AutoServer())...
Listening on http://0.0.0.0:80/
Hit Ctrl-C to quit.

182.254.86.154 - - [01/May/2018 18:32:05] "POST /?signature=4230c5ac333f7f0841b6c9d50bd36164abc2345e&timestamp=1525170724&nonce=2051886401&openid=o2NddxHhZloQV55azmx8zVXv9mAQ HTTP/1.1" 200 467
182.254.86.149 - - [01/May/2018 18:32:06] "POST /?signature=0b9603c7339eddac6a7e8ec761eebe8560919839&timestamp=1525170726&nonce=1911952294&openid=o2NddxHhZloQV55azmx8zVXv9mAQ HTTP/1.1" 200 326
[E 180501 18:32:07 robot:405] Catch an exception
    Traceback (most recent call last):
      File "/usr/local/lib/python3.4/dist-packages/werobot/robot.py", line 399, in get_reply
        reply = handler(*args)
      File "reply_from_pymysql.py", line 124, in hello
        print('\u300a%s\u300b'%message.content)
    UnicodeEncodeError: 'ascii' codec can't encode characters in position 0-4: ordinal not in range(128)
[W 180501 18:32:07 robot:419] No handler responded message <werobot.messages.messages.TextMessage object at 0xb6a8e3ac>
182.254.86.144 - - [01/May/2018 18:32:07] "POST /?signature=59054bfaa0e14d88b0e1357cdbff7f5277dce4c8&timestamp=1525170727&nonce=309995674&openid=o2NddxHhZloQV55azmx8zVXv9mAQ HTTP/1.1" 200 0
[E 180501 18:32:10 robot:405] Catch an exception
    Traceback (most recent call last):
      File "/usr/local/lib/python3.4/dist-packages/werobot/robot.py", line 399, in get_reply
        reply = handler(*args)
      File "reply_from_pymysql.py", line 124, in hello
        print('\u300a%s\u300b'%message.content)
    UnicodeEncodeError: 'ascii' codec can't encode characters in position 0-4: ordinal not in range(128)
[W 180501 18:32:10 robot:419] No handler responded message <werobot.messages.messages.TextMessage object at 0xb6a8eb4c>
182.254.86.150 - - [01/May/2018 18:32:10] "POST /?signature=c22585f0c0a72695725f98059056405f29977971&timestamp=1525170730&nonce=512120598&openid=o2NddxHhZloQV55azmx8zVXv9mAQ HTTP/1.1" 200 0
[E 180501 18:32:18 robot:405] Catch an exception
    Traceback (most recent call last):
      File "/usr/local/lib/python3.4/dist-packages/werobot/robot.py", line 399, in get_reply
        reply = handler(*args)
      File "reply_from_pymysql.py", line 124, in hello
        print('\u300a%s\u300b'%message.content)
    UnicodeEncodeError: 'ascii' codec can't encode characters in position 0-4: ordinal not in range(128)
[W 180501 18:32:18 robot:419] No handler responded message <werobot.messages.messages.TextMessage object at 0xb6a8edac>
182.254.86.149 - - [01/May/2018 18:32:18] "POST /?signature=82aa502a7b20102e54133aa216dcacb8acff58d4&timestamp=1525170738&nonce=1343583269&openid=o2NddxHhZloQV55azmx8zVXv9mAQ HTTP/1.1" 200 0
[E 180501 18:32:19 robot:405] Catch an exception
    Traceback (most recent call last):
      File "/usr/local/lib/python3.4/dist-packages/werobot/robot.py", line 399, in get_reply
        reply = handler(*args)
      File "reply_from_pymysql.py", line 124, in hello
        print('\u300a%s\u300b'%message.content)
    UnicodeEncodeError: 'ascii' codec can't encode characters in position 0-5: ordinal not in range(128)
[W 180501 18:32:19 robot:419] No handler responded message <werobot.messages.messages.TextMessage object at 0xb6a8ef2c>
182.254.86.144 - - [01/May/2018 18:32:19] "POST /?signature=78dfffc617f7cab8735e28e47edb772e85fc7105&timestamp=1525170739&nonce=694888596&openid=o2NddxIjlgUSNnv49z78QvF1yryU HTTP/1.1" 200 0
[W 180501 18:32:21 robot:419] No handler responded message <werobot.messages.events.ViewEvent object at 0xb6ab72cc>
182.254.86.140 - - [01/May/2018 18:32:21] "POST /?signature=3c41b2b09fa89955eca2567530614cadf5cdd261&timestamp=1525170741&nonce=276616865&openid=o2NddxN20MA-QlgzxBd6RHAeAHv8 HTTP/1.1" 200 0
[W 180501 18:32:28 robot:419] No handler responded message <werobot.messages.events.ViewEvent object at 0xb6ab75ec>
182.254.86.140 - - [01/May/2018 18:32:28] "POST /?signature=59469bedda181b4db1f80032007d1fdaece55f67&timestamp=1525170747&nonce=1103668037&openid=onD4307z2GaHHSrlG040IlPcYp1Q HTTP/1.1" 200 0
[E 180501 18:32:30 robot:405] Catch an exception
    Traceback (most recent call last):
      File "/usr/local/lib/python3.4/dist-packages/werobot/robot.py", line 399, in get_reply
        reply = handler(*args)
      File "reply_from_pymysql.py", line 124, in hello
        print('\u300a%s\u300b'%message.content)
    UnicodeEncodeError: 'ascii' codec can't encode characters in position 0-6: ordinal not in range(128)
[W 180501 18:32:30 robot:419] No handler responded message <werobot.messages.messages.TextMessage object at 0xb6ab79ac>
182.254.86.145 - - [01/May/2018 18:32:30] "POST /?signature=78d1cd08aae08d4099e907e3b6e0c98a571eb8e4&timestamp=1525170750&nonce=1966592466&openid=o2NddxN20MA-QlgzxBd6RHAeAHv8 HTTP/1.1" 200 0
[E 180501 18:32:33 robot:405] Catch an exception
    Traceback (most recent call last):
      File "/usr/local/lib/python3.4/dist-packages/werobot/robot.py", line 399, in get_reply
        reply = handler(*args)
      File "reply_from_pymysql.py", line 124, in hello
        print('\u300a%s\u300b'%message.content)
    UnicodeEncodeError: 'ascii' codec can't encode characters in position 0-4: ordinal not in range(128)
[W 180501 18:32:33 robot:419] No handler responded message <werobot.messages.messages.TextMessage object at 0xb6ab7ccc>
182.254.86.144 - - [01/May/2018 18:32:33] "POST /?signature=e3cbf08d82b0810e484049ff1a98bb0f7a2162e6&timestamp=1525170753&nonce=2087673341&openid=o2NddxHhZloQV55azmx8zVXv9mAQ HTTP/1.1" 200 0
